Workbook

Sheet RISICOREGISTER
E1: Project | F1: Robbenoord Wieringerwerf
E2: TSB (conform BTO) | F2: 798562.59
E3: Projectgrootte (zie tabel) | F3: =IF(F2<5000000,"Klein project",IF(F2<=12000000,"Middelgroot project","Groot project")) -> Klein project
E4: Opsteller | F4: Wouter Busstra
E5: Datum laatste actualisatie | F5: 03-06-2026
E6: Bouwteam | F6: {=SUM(SUMIFS($AI$12:$AI$112,$H$12:$H$112,{"Voorstel";"Vigerend";"Beheerst"},$K$12:$K$112,E6))} -> 48125
E7: Uitvoering | F7: {=SUM(SUMIFS($AI$12:$AI$112,$H$12:$H$112,{"Voorstel";"Actueel";"Vigerend";"Beheerst"},$K$12:$K$112,E7))} -> 216875
E8: Totaal restrisico | F8: =SUM(F6:F7) -> 265000
B10: OMSCHRIJVING | L10: KWANTIFICERING | S10: FINANCIËLE KWANTIFICERING | V10: BEHEERSING | Z10: RESTRISICO | AG10: KANS | AH10: FINANCIËLE KWANTIFICERING | AJ10: TIJDSIMPACT
B11: ID | C11: Deelproject | D11: Ongewenste gebeurtenis | E11: Oorzaak(en) | F11: Gevolg(en) | G11: Opmerking risico | H11: Status risico | I11: Risico-eigenaar | J11: Allocatie | K11: Fase | L11: Kans | M11: Tijd | N11: Geld | O11: Kwaliteit | P11: Veiligheid | Q11: Omgeving | R11: Risico | S11: Kans | T11: Geld | U11: Initieel risicio bedrag | V11: Beheersmaatregel | W11: Actiehouder | X11: Status | Y11: Opmerkingen | Z11: Kans | AA11: Tijd | AB11: Geld | AC11: Kwaliteit | AD11: Veiligheid | AE11: Omgeving | AF11: Risico | AG11: Kans | AH11: Rekenwaarde kosten | AI11: Restrisico bedrag | AJ11: Tijdsimpact
B12: 1 | D12: De benodigde ZRO's / grondaankopen zijn niet voor start uitvoering ondertekend. | H12: Vervallen | J12: Liander | K12: Bouwteam | R12: =IFERROR(Tabel2[[#This Row],[Kans]]*SUM(Tabel2[[#This Row],[Tijd]:[Omgeving]]),0) -> 0 | S12: =IFERROR(VLOOKUP(Tabel2[[#This Row],[Kans]],#REF!,9,0),0) -> 0 | T12: =IFERROR(VLOOKUP(Tabel2[[#This Row],[Geld]],#REF!,12,0),0) -> 0 | U12: =Tabel2[[#This Row],[Kans ]]*Tabel2[[#This Row],[Geld ]] -> 0 | V12: 1. Tijdig in VO fase perceeleigenaren benaderen 2. Bij geen akkoord direct gedoogconstructie opstarten 3. Indien bezwaar laatste tekening niet in kleine tijd kan worden opgelost alvast starten met ZRO procedure muv de laatste tekening. 4. Moeilijke percelen naar achteren zetten in uitvoeringsplanning 5. NAOK ondertekenen zonder alle ZRO's mits goed onderbouwd | W12: 1. Isabel Gheza 2. Isabel Gheza 3. Jarno Sman 4. Johan van Dronkelaar 5. Johan van Dronkelaar | X12: 1. Gereed 2. Besluit: Wacht op uitvoering 3. Gereed 4. 12-09-2025 5. 12-09-2025 | Z12: 5 | AA12: 5 | AB12: 2 | AC12: 0 | AD12: 0 | AE12: 4 | AF12: =IFERROR(Tabel2[[#This Row],[Kans ]]*SUM(Tabel2[[#This Row],[Tijd ]:[Omgeving ]]),0) -> 55 | AG12: =VLOOKUP(Tabel2[[#This Row],[Kans ]],KWANTIFICEERTABELLEN!$B$19:$J$26,8,FALSE()) -> 0.4 | AH12: =IF(F$2<KWANTIFICEERTABELLEN!B$4,VLOOKUP(Tabel2[[#This Row],[Geld ]],KWANTIFICEERTABELLEN!$B$6:$J$13,9,FALSE()), IF(AND(F$2>KWANTIFICEERTABELLEN!B$4,$F$2<KWANTIFICEERTABELLEN!B$30),VLOOKUP(Tabel2[[#This Row],[Geld ]],KWANTIFICEERTABELLEN!$B$19:$J$26,9,FALSE()), IF(F$2>KWANTIFICEERTABELLEN!B$30,VLOOKUP(Tabel2[[#This Row],[Geld ]],KWANTIFICEERTABELLEN!$B$32:$J$39,9,FALSE()),))) -> 7500 | AI12: =IFERROR(Tabel2[[#This Row],[Kans ]]*Tabel2[[#This Row],[Rekenwaarde kosten]],0) -> 3000 | AJ12: =IF(F$2<KWANTIFICEERTABELLEN!B$4,VLOOKUP(Tabel2[[#This Row],[Tijd ]],KWANTIFICEERTABELLEN!$B$6:$D$13,3,FALSE()), IF(AND(F$2>KWANTIFICEERTABELLEN!B$4,$F$2<KWANTIFICEERTABELLEN!B$30),VLOOKUP(Tabel2[[#This Row],[Tijd ]],KWANTIFICEERTABELLEN!$B$19:$D$26,3,FALSE()), IF(F$2>KWANTIFICEERTABELLEN!B$30,VLOOKUP(Tabel2[[#This Row],[Tijd ]],KWANTIFICEERTABELLEN!$B$32:$D$39,3,FALSE()),))) -> 4 - 6 weken
B13: 56 | C13: Beiden | D13: Schade aan particulieren percelen | E13: 1. Onzorgvuldige uitvoering 2. Werkafspraken niet nakomen | F13: 1. Perceeleigenaar ontevreden 2. Claims bij Liander 3. Imagoschade 4. Herstelwerkzaamheden | H13: Vigerend | I13: Onno Cavalini | J13: A.Hak | K13: Uitvoering | L13: 1. Warm contact houden met bevoegd gezag | P13: 1 | Q13: 3 | R13: 2 | S13: 0 | T13: 0 | U13: 0 | V13: 1. Werken conform afspraken 2. Aantonen werken conform afspraken 3. Begin- en eindopname 4. Adequate klachtenafhandeling | W13: Uitvoering | X13: Open | Z13: 6 | AA13: 2 | AB13: 4 | AC13: 5 | AD13: 1 | AE13: 2 | AF13: =IFERROR(Tabel2[[#This Row],[Kans ]]*SUM(Tabel2[[#This Row],[Tijd ]:[Omgeving ]]),0) -> 84 | AG13: =VLOOKUP(Tabel2[[#This Row],[Kans ]],KWANTIFICEERTABELLEN!$B$19:$J$26,8,FALSE()) -> 0.5 | AH13: =IF(F$2<KWANTIFICEERTABELLEN!B$4,VLOOKUP(Tabel2[[#This Row],[Geld ]],KWANTIFICEERTABELLEN!$B$6:$J$13,9,FALSE()), IF(AND(F$2>KWANTIFICEERTABELLEN!B$4,$F$2<KWANTIFICEERTABELLEN!B$30),VLOOKUP(Tabel2[[#This Row],[Geld ]],KWANTIFICEERTABELLEN!$B$19:$J$26,9,FALSE()), IF(F$2>KWANTIFICEERTABELLEN!B$30,VLOOKUP(Tabel2[[#This Row],[Geld ]],KWANTIFICEERTABELLEN!$B$32:$J$39,9,FALSE()),))) -> 37500 | AI13: =IFERROR(Tabel2[[#This Row],[Kans ]]*Tabel2[[#This Row],[Rekenwaarde kosten]],0) -> 18750 | AJ13: =IF(F$2<KWANTIFICEERTABELLEN!B$4,VLOOKUP(Tabel2[[#This Row],[Tijd ]],KWANTIFICEERTABELLEN!$B$6:$D$13,3,FALSE()), IF(AND(F$2>KWANTIFICEERTABELLEN!B$4,$F$2<KWANTIFICEERTABELLEN!B$30),VLOOKUP(Tabel2[[#This Row],[Tijd ]],KWANTIFICEERTABELLEN!$B$19:$D$26,3,FALSE()), IF(F$2>KWANTIFICEERTABELLEN!B$30,VLOOKUP(Tabel2[[#This Row],[Tijd ]],KWANTIFICEERTABELLEN!$B$32:$D$39,3,FALSE()),))) -> 0.5 - 1 weken
B14: 3 | D14: De ontwerp- en omgevingsproducten worden niet conform planning opgeleverd. | H14: Vervallen | J14: A.Hak | K14: Bouwteam | R14: =IFERROR(Tabel2[[#This Row],[Kans]]*SUM(Tabel2[[#This Row],[Tijd]:[Omgeving]]),0) -> 0 | V14: 1. Capaciteit engineering op perceel monitoren 2. Locaties voorstellen en bespreken met perceeleigenaren 3. Escaleren naar Job Plas om TM'er aanhaken op het project 4. In overleg met ambtenaar vergunningsaanvraag in delen indienen | W14: 1. Thomas Snoep 2. Isabel Gheza 3. Thomas Snoep 4. Isabel Gheza | X14: 1. Continu 2. Gereed 3. Gereed 4. 28-5-2025 | Z14: 6 | AA14: 6 | AB14: 2 | AC14: 0 | AD14: 0 | AE14: 0 | AF14: =IFERROR(Tabel2[[#This Row],[Kans ]]*SUM(Tabel2[[#This Row],[Tijd ]:[Omgeving ]]),0) -> 48 | AG14: =VLOOKUP(Tabel2[[#This Row],[Kans ]],KWANTIFICEERTABELLEN!$B$19:$J$26,8,FALSE()) -> 0.5 | AH14: =IF(F$2<KWANTIFICEERTABELLEN!B$4,VLOOKUP(Tabel2[[#This Row],[Geld ]],KWANTIFICEERTABELLEN!$B$6:$J$13,9,FALSE()), IF(AND(F$2>KWANTIFICEERTABELLEN!B$4,$F$2<KWANTIFICEERTABELLEN!B$30),VLOOKUP(Tabel2[[#This Row],[Geld ]],KWANTIFICEERTABELLEN!$B$19:$J$26,9,FALSE()), IF(F$2>KWANTIFICEERTABELLEN!B$30,VLOOKUP(Tabel2[[#This Row],[Geld ]],KWANTIFICEERTABELLEN!$B$32:$J$39,9,FALSE()),))) -> 7500 | AI14: =IFERROR(Tabel2[[#This Row],[Kans ]]*Tabel2[[#This Row],[Rekenwaarde kosten]],0) -> 3750 | AJ14: =IF(F$2<KWANTIFICEERTABELLEN!B$4,VLOOKUP(Tabel2[[#This Row],[Tijd ]],KWANTIFICEERTABELLEN!$B$6:$D$13,3,FALSE()), IF(AND(F$2>KWANTIFICEERTABELLEN!B$4,$F$2<KWANTIFICEERTABELLEN!B$30),VLOOKUP(Tabel2[[#This Row],[Tijd ]],KWANTIFICEERTABELLEN!$B$19:$D$26,3,FALSE()), IF(F$2>KWANTIFICEERTABELLEN!B$30,VLOOKUP(Tabel2[[#This Row],[Tijd ]],KWANTIFICEERTABELLEN!$B$32:$D$39,3,FALSE()),))) -> 6 - 8 weken
B15: 4 | D15: Uit het uit te voeren F&F onderzoek blijken aanvullen maatregelen nodig gedurende de uitvoering voor beschermde soorten aanwezig te zijn. (Met name voor de ruggstreeppad) | H15: Vervallen | J15: A.Hak | K15: Uitvoering | R15: =IFERROR(Tabel2[[#This Row],[Kans]]*SUM(Tabel2[[#This Row],[Tijd]:[Omgeving]]),0) -> 0 | V15: 1. In de VO-fase een quick scan uitvoeren. 2. Na quick scan vervolg onderzoek uitvoeren. Hierbij het raakvlak met planing in beeld brengen. 3. Buffer van 50 meter aan beide zijde van het trace meenemen in de F&F onderzoeken. 4. In overleg met TM maatwerkafspraken maken qua onderzoeksgebied. 5. Bij Movares urgentie benadrukken voor stukken OD (Werkprotocol) | W15: 1. Isabel Gheza 2. Isabel Gheza 3. Isabel Gheza 4. Isabel Gheza 5. Isabel Gheza | X15: 1. Gereed 2. Gereed 3. Gereed 4. Gereed 5. Gereed | Z15: 4 | AA15: 5 | AB15: 3 | AC15: 0 | AD15: 0 | AE15: 0 | AF15: =IFERROR(Tabel2[[#This Row],[Kans ]]*SUM(Tabel2[[#This Row],[Tijd ]:[Omgeving ]]),0) -> 32 | AG15: =VLOOKUP(Tabel2[[#This Row],[Kans ]],KWANTIFICEERTABELLEN!$B$19:$J$26,8,FALSE()) -> 0.3 | AH15: =IF(F$2<KWANTIFICEERTABELLEN!B$4,VLOOKUP(Tabel2[[#This Row],[Geld ]],KWANTIFICEERTABELLEN!$B$6:$J$13,9,FALSE()), IF(AND(F$2>KWANTIFICEERTABELLEN!B$4,$F$2<KWANTIFICEERTABELLEN!B$30),VLOOKUP(Tabel2[[#This Row],[Geld ]],KWANTIFICEERTABELLEN!$B$19:$J$26,9,FALSE()), IF(F$2>KWANTIFICEERTABELLEN!B$30,VLOOKUP(Tabel2[[#This Row],[Geld ]],KWANTIFICEERTABELLEN!$B$32:$J$39,9,FALSE()),))) -> 17500 | AI15: =IFERROR(Tabel2[[#This Row],[Kans ]]*Tabel2[[#This Row],[Rekenwaarde kosten]],0) -> 5250 | AJ15: =IF(F$2<KWANTIFICEERTABELLEN!B$4,VLOOKUP(Tabel2[[#This Row],[Tijd ]],KWANTIFICEERTABELLEN!$B$6:$D$13,3,FALSE()), IF(AND(F$2>KWANTIFICEERTABELLEN!B$4,$F$2<KWANTIFICEERTABELLEN!B$30),VLOOKUP(Tabel2[[#This Row],[Tijd ]],KWANTIFICEERTABELLEN!$B$19:$D$26,3,FALSE()), IF(F$2>KWANTIFICEERTABELLEN!B$30,VLOOKUP(Tabel2[[#This Row],[Tijd ]],KWANTIFICEERTABELLEN!$B$32:$D$39,3,FALSE()),))) -> 4 - 6 weken
B16: 5 | D16: Aanpassingen vergunningen worden niet op tijd goedgekeurd door gemeente Hollands Kroon. | E16: 1. Onvoldoende capaciteit bij de gemeente Hollands Kroon voor tijdige beoordeling; 2. Aanpassingen aan het ontwerp of tracé na indiening vereisen herindieningsronden; 3. Indieningseisen onduidelijk of de gemeente hanteert een aanvullende beslistermijn. | F16: 1. Vertraging in de voorbereidingsfase doordat werkzaamheden niet mogen starten; 2. IBN datum verschuift, met extra stand-bykosten voor personeel en materieel; 3. Rework engineering bij afgekeurde vergunningsindieningsronden. | G16: Afgetikt bij MSR (Schelpenbolweg 11 en 15) | H16: Vervallen | I16: Isabel Gheza | J16: Liander | K16: Bouwteam | L16: 5 | M16: 6 | N16: 2 | O16: 0 | P16: 0 | Q16: 4 | R16: =IFERROR(Tabel2[[#This Row],[Kans]]*SUM(Tabel2[[#This Row],[Tijd]:[Omgeving]]),0) -> 60 | V16: 1. Tijdig opstarten van het vergunningentraject 2. In de planning 6 wkn extra behandeltermijn opnemen. 3. Liander voert escalatiegesprekken om zaken sneller te laten verlopen | W16: 1. Isabel Gheza 2. Isabel Gheza 3. Liander | X16: 1. Gereed 2. Gereed 3. Gereed | Z16: 2 | AA16: 6 | AB16: 2 | AC16: 0 | AD16: 0 | AE16: 4 | AF16: =IFERROR(Tabel2[[#This Row],[Kans ]]*SUM(Tabel2[[#This Row],[Tijd ]:[Omgeving ]]),0) -> 24 | AG16: =VLOOKUP(Tabel2[[#This Row],[Kans ]],KWANTIFICEERTABELLEN!$B$19:$J$26,8,FALSE()) -> 0.1 | AH16: =IF(F$2<KWANTIFICEERTABELLEN!B$4,VLOOKUP(Tabel2[[#This Row],[Geld ]],KWANTIFICEERTABELLEN!$B$6:$J$13,9,FALSE()), IF(AND(F$2>KWANTIFICEERTABELLEN!B$4,$F$2<KWANTIFICEERTABELLEN!B$30),VLOOKUP(Tabel2[[#This Row],[Geld ]],KWANTIFICEERTABELLEN!$B$19:$J$26,9,FALSE()), IF(F$2>KWANTIFICEERTABELLEN!B$30,VLOOKUP(Tabel2[[#This Row],[Geld ]],KWANTIFICEERTABELLEN!$B$32:$J$39,9,FALSE()),))) -> 7500 | AI16: =IFERROR(Tabel2[[#This Row],[Kans ]]*Tabel2[[#This Row],[Rekenwaarde kosten]],0) -> 750 | AJ16: =IF(F$2<KWANTIFICEERTABELLEN!B$4,VLOOKUP(Tabel2[[#This Row],[Tijd ]],KWANTIFICEERTABELLEN!$B$6:$D$13,3,FALSE()), IF(AND(F$2>KWANTIFICEERTABELLEN!B$4,$F$2<KWANTIFICEERTABELLEN!B$30),VLOOKUP(Tabel2[[#This Row],[Tijd ]],KWANTIFICEERTABELLEN!$B$19:$D$26,3,FALSE()), IF(F$2>KWANTIFICEERTABELLEN!B$30,VLOOKUP(Tabel2[[#This Row],[Tijd ]],KWANTIFICEERTABELLEN!$B$32:$D$39,3,FALSE()),))) -> 6 - 8 weken
B17: 6 | D17: Informatie vanuit DRILCON wordt niet tijdig opgeleverd voor opleveren DO | H17: Vervallen | J17: Bouwteam | K17: Bouwteam | R17: =IFERROR(Tabel2[[#This Row],[Kans]]*SUM(Tabel2[[#This Row],[Tijd]:[Omgeving]]),0) -> 0 | V17: 1. Druk uitoefenen en nut en noodzaak van opleveren tekeningen toelichten aan DRILCON | W17: 1. Thomas Snoep | X17: 1. 10-04-2025 | AF17: =IFERROR(Tabel2[[#This Row],[Kans ]]*SUM(Tabel2[[#This Row],[Tijd ]:[Omgeving ]]),0) -> 0 | AG17: =VLOOKUP(Tabel2[[#This Row],[Kans ]],KWANTIFICEERTABELLEN!$B$19:$J$26,8,FALSE()) -> 0 | AH17: =IF(F$2<KWANTIFICEERTABELLEN!B$4,VLOOKUP(Tabel2[[#This Row],[Geld ]],KWANTIFICEERTABELLEN!$B$6:$J$13,9,FALSE()), IF(AND(F$2>KWANTIFICEERTABELLEN!B$4,$F$2<KWANTIFICEERTABELLEN!B$30),VLOOKUP(Tabel2[[#This Row],[Geld ]],KWANTIFICEERTABELLEN!$B$19:$J$26,9,FALSE()), IF(F$2>KWANTIFICEERTABELLEN!B$30,VLOOKUP(Tabel2[[#This Row],[Geld ]],KWANTIFICEERTABELLEN!$B$32:$J$39,9,FALSE()),))) -> 0 | AI17: =IFERROR(Tabel2[[#This Row],[Kans ]]*Tabel2[[#This Row],[Rekenwaarde kosten]],0) -> 0 | AJ17: =IF(F$2<KWANTIFICEERTABELLEN!B$4,VLOOKUP(Tabel2[[#This Row],[Tijd ]],KWANTIFICEERTABELLEN!$B$6:$D$13,3,FALSE()), IF(AND(F$2>KWANTIFICEERTABELLEN!B$4,$F$2<KWANTIFICEERTABELLEN!B$30),VLOOKUP(Tabel2[[#This Row],[Tijd ]],KWANTIFICEERTABELLEN!$B$19:$D$26,3,FALSE()), IF(F$2>KWANTIFICEERTABELLEN!B$30,VLOOKUP(Tabel2[[#This Row],[Tijd ]],KWANTIFICEERTABELLEN!$B$32:$D$39,3,FALSE()),))) -> Geen impact
B18: 7 | D18: De efficientie van de samenwerking tussen verschillende disciplines verloopt niet optimaal. | H18: Vervallen | J18: Bouwteam | K18: Uitvoering | R18: =IFERROR(Tabel2[[#This Row],[Kans]]*SUM(Tabel2[[#This Row],[Tijd]:[Omgeving]]),0) -> 0 | V18: 1. Structureel aandacht voor processen en check hierop 2. Clearly en planning delen op het scherm 3. Producten eerder voorleggen / valideren | W18: 1. Jos Verstappen 2. PM 3. TM | AF18: =IFERROR(Tabel2[[#This Row],[Kans ]]*SUM(Tabel2[[#This Row],[Tijd ]:[Omgeving ]]),0) -> 0 | AG18: =VLOOKUP(Tabel2[[#This Row],[Kans ]],KWANTIFICEERTABELLEN!$B$19:$J$26,8,FALSE()) -> 0 | AH18: =IF(F$2<KWANTIFICEERTABELLEN!B$4,VLOOKUP(Tabel2[[#This Row],[Geld ]],KWANTIFICEERTABELLEN!$B$6:$J$13,9,FALSE()), IF(AND(F$2>KWANTIFICEERTABELLEN!B$4,$F$2<KWANTIFICEERTABELLEN!B$30),VLOOKUP(Tabel2[[#This Row],[Geld ]],KWANTIFICEERTABELLEN!$B$19:$J$26,9,FALSE()), IF(F$2>KWANTIFICEERTABELLEN!B$30,VLOOKUP(Tabel2[[#This Row],[Geld ]],KWANTIFICEERTABELLEN!$B$32:$J$39,9,FALSE()),))) -> 0 | AI18: =IFERROR(Tabel2[[#This Row],[Kans ]]*Tabel2[[#This Row],[Rekenwaarde kosten]],0) -> 0 | AJ18: =IF(F$2<KWANTIFICEERTABELLEN!B$4,VLOOKUP(Tabel2[[#This Row],[Tijd ]],KWANTIFICEERTABELLEN!$B$6:$D$13,3,FALSE()), IF(AND(F$2>KWANTIFICEERTABELLEN!B$4,$F$2<KWANTIFICEERTABELLEN!B$30),VLOOKUP(Tabel2[[#This Row],[Tijd ]],KWANTIFICEERTABELLEN!$B$19:$D$26,3,FALSE()), IF(F$2>KWANTIFICEERTABELLEN!B$30,VLOOKUP(Tabel2[[#This Row],[Tijd ]],KWANTIFICEERTABELLEN!$B$32:$D$39,3,FALSE()),))) -> Geen impact
B19: 21 | C19: DP1 (Hoofdtracé) | D19: Vergunning voor 2 MSR's (schelpenbolweg 15 en 11) wordt niet (tijdig) verleend door Gemeente Hollands Kroon | E19: 1. Onvoldoende capaciteit bij de gemeente voor tijdige vergunningverlening; 2. Indieningseisen onduidelijk of de gemeente stelt onredelijke eisen; 3. Gemeente neemt een aanvullende beslistermijn op, of er worden bezwaarproceduresprocedures gestart. | F19: 1. Werkzaamheden kunnen niet tijdig worden gestart, waardoor de IBN datum verschuift; 2. Extra stand-bykosten voor personeel, materieel en de projectorganisatie; 3. Mogelijke herindieningsronde bij afkeur, met extra engineering- en proceskosten. | H19: Vigerend | I19: Isabel Gheza | J19: Bouwteam | K19: Bouwteam | L19: 5 | M19: 6 | N19: 0 | O19: 0 | P19: 0 | Q19: 4 | R19: =IFERROR(Tabel2[[#This Row],[Kans]]*SUM(Tabel2[[#This Row],[Tijd]:[Omgeving]]),0) -> 50 | V19: 1. Warm contact houden met de Gemeente | W19: 1. Isabel Gheza | X19: 1. Gereed | Z19: 4 | AA19: 6 | AB19: 6 | AC19: 6 | AD19: 0 | AE19: 1 | AF19: =IFERROR(Tabel2[[#This Row],[Kans ]]*SUM(Tabel2[[#This Row],[Tijd ]:[Omgeving ]]),0) -> 76 | AG19: =VLOOKUP(Tabel2[[#This Row],[Kans ]],KWANTIFICEERTABELLEN!$B$19:$J$26,8,FALSE()) -> 0.3 | AH19: =IF(F$2<KWANTIFICEERTABELLEN!B$4,VLOOKUP(Tabel2[[#This Row],[Geld ]],KWANTIFICEERTABELLEN!$B$6:$J$13,9,FALSE()), IF(AND(F$2>KWANTIFICEERTABELLEN!B$4,$F$2<KWANTIFICEERTABELLEN!B$30),VLOOKUP(Tabel2[[#This Row],[Geld ]],KWANTIFICEERTABELLEN!$B$19:$J$26,9,FALSE()), IF(F$2>KWANTIFICEERTABELLEN!B$30,VLOOKUP(Tabel2[[#This Row],[Geld ]],KWANTIFICEERTABELLEN!$B$32:$J$39,9,FALSE()),))) -> 87500 | AI19: =IFERROR(Tabel2[[#This Row],[Kans ]]*Tabel2[[#This Row],[Rekenwaarde kosten]],0) -> 26250 | AJ19: =IF(F$2<KWANTIFICEERTABELLEN!B$4,VLOOKUP(Tabel2[[#This Row],[Tijd ]],KWANTIFICEERTABELLEN!$B$6:$D$13,3,FALSE()), IF(AND(F$2>KWANTIFICEERTABELLEN!B$4,$F$2<KWANTIFICEERTABELLEN!B$30),VLOOKUP(Tabel2[[#This Row],[Tijd ]],KWANTIFICEERTABELLEN!$B$19:$D$26,3,FALSE()), IF(F$2>KWANTIFICEERTABELLEN!B$30,VLOOKUP(Tabel2[[#This Row],[Tijd ]],KWANTIFICEERTABELLEN!$B$32:$D$39,3,FALSE()),))) -> 6 - 8 weken
B20: 9 | D20: Belastbaarheidsberekeningen zijn niet voor GSU uitgevoerd. | H20: Vervallen | J20: Bouwteam | K20: Bouwteam | R20: =IFERROR(Tabel2[[#This Row],[Kans]]*SUM(Tabel2[[#This Row],[Tijd]:[Omgeving]]),0) -> 0 | V20: 1. Keuze maken om een Boorbuis onderwater te zetten 2. Keuze maken om Dikkere diameter (van 240 naar 630) toe te passen. 3. Controleren of bij het project een belastbaarheidsberekening moet worden uitgevoerd bij Reimer Lap | W20: 1. Isabel Gheza 2. Isabel Gheza 3. Isabel Gheza | X20: 1. 9-05-2025 2. 9-05-2025 3. 9-05-2025 | AF20: =IFERROR(Tabel2[[#This Row],[Kans ]]*SUM(Tabel2[[#This Row],[Tijd ]:[Omgeving ]]),0) -> 0 | AG20: =VLOOKUP(Tabel2[[#This Row],[Kans ]],KWANTIFICEERTABELLEN!$B$19:$J$26,8,FALSE()) -> 0 | AH20: =IF(F$2<KWANTIFICEERTABELLEN!B$4,VLOOKUP(Tabel2[[#This Row],[Geld ]],KWANTIFICEERTABELLEN!$B$6:$J$13,9,FALSE()), IF(AND(F$2>KWANTIFICEERTABELLEN!B$4,$F$2<KWANTIFICEERTABELLEN!B$30),VLOOKUP(Tabel2[[#This Row],[Geld ]],KWANTIFICEERTABELLEN!$B$19:$J$26,9,FALSE()), IF(F$2>KWANTIFICEERTABELLEN!B$30,VLOOKUP(Tabel2[[#This Row],[Geld ]],KWANTIFICEERTABELLEN!$B$32:$J$39,9,FALSE()),))) -> 0 | AI20: =IFERROR(Tabel2[[#This Row],[Kans ]]*Tabel2[[#This Row],[Rekenwaarde kosten]],0) -> 0 | AJ20: =IF(F$2<KWANTIFICEERTABELLEN!B$4,VLOOKUP(Tabel2[[#This Row],[Tijd ]],KWANTIFICEERTABELLEN!$B$6:$D$13,3,FALSE()), IF(AND(F$2>KWANTIFICEERTABELLEN!B$4,$F$2<KWANTIFICEERTABELLEN!B$30),VLOOKUP(Tabel2[[#This Row],[Tijd ]],KWANTIFICEERTABELLEN!$B$19:$D$26,3,FALSE()), IF(F$2>KWANTIFICEERTABELLEN!B$30,VLOOKUP(Tabel2[[#This Row],[Tijd ]],KWANTIFICEERTABELLEN!$B$32:$D$39,3,FALSE()),))) -> Geen impact
B21: 10 | D21: Data waarop nieuwe stations worden geplaatst worden niet gehaald | H21: Vervallen | J21: Bouwteam | K21: Uitvoering | R21: =IFERROR(Tabel2[[#This Row],[Kans]]*SUM(Tabel2[[#This Row],[Tijd]:[Omgeving]]),0) -> 0 | V21: 1. Stations waar ruggstreeppad is gevestigd los halen uit de aanvraag voor inlussen van de kabels bij de stations. 2. In BTO mogelijke vertraging doornemen -> Wordt in weeklys behandeld. 3. Onderzoeken of Stations al wel te plaatsen zijn (zonder sleuven) | W21: 1. Jarno Sman 2. Johan van Dronkelaar 3. Thijs Baauw | X21: 1. 8-10-2025 2. Gereed 3. 8-7-2025 | AF21: =IFERROR(Tabel2[[#This Row],[Kans ]]*SUM(Tabel2[[#This Row],[Tijd ]:[Omgeving ]]),0) -> 0 | AG21: =VLOOKUP(Tabel2[[#This Row],[Kans ]],KWANTIFICEERTABELLEN!$B$19:$J$26,8,FALSE()) -> 0 | AH21: =IF(F$2<KWANTIFICEERTABELLEN!B$4,VLOOKUP(Tabel2[[#This Row],[Geld ]],KWANTIFICEERTABELLEN!$B$6:$J$13,9,FALSE()), IF(AND(F$2>KWANTIFICEERTABELLEN!B$4,$F$2<KWANTIFICEERTABELLEN!B$30),VLOOKUP(Tabel2[[#This Row],[Geld ]],KWANTIFICEERTABELLEN!$B$19:$J$26,9,FALSE()), IF(F$2>KWANTIFICEERTABELLEN!B$30,VLOOKUP(Tabel2[[#This Row],[Geld ]],KWANTIFICEERTABELLEN!$B$32:$J$39,9,FALSE()),))) -> 0 | AI21: =IFERROR(Tabel2[[#This Row],[Kans ]]*Tabel2[[#This Row],[Rekenwaarde kosten]],0) -> 0 | AJ21: =IF(F$2<KWANTIFICEERTABELLEN!B$4,VLOOKUP(Tabel2[[#This Row],[Tijd ]],KWANTIFICEERTABELLEN!$B$6:$D$13,3,FALSE()), IF(AND(F$2>KWANTIFICEERTABELLEN!B$4,$F$2<KWANTIFICEERTABELLEN!B$30),VLOOKUP(Tabel2[[#This Row],[Tijd ]],KWANTIFICEERTABELLEN!$B$19:$D$26,3,FALSE()), IF(F$2>KWANTIFICEERTABELLEN!B$30,VLOOKUP(Tabel2[[#This Row],[Tijd ]],KWANTIFICEERTABELLEN!$B$32:$D$39,3,FALSE()),))) -> Geen impact
B22: 11 | D22: MSR zijn niet tijdig geplaatst voor het opvolgen vanuit de uitvoering (inlussen van de kabel) | G22: Onderverdeeld in losse risico's | H22: Vervallen | J22: Liander | K22: Uitvoering | R22: =IFERROR(Tabel2[[#This Row],[Kans]]*SUM(Tabel2[[#This Row],[Tijd]:[Omgeving]]),0) -> 0 | V22: 1. Bij perceeleigenaar op gesprek gaan over de te plaatsen MSR'en 2. Stationswerken pas laten starten bij ondertekenen grondaankoop. 3. In de planning rekening houden met 14 weken GR en 6 weken navolgend voor het plaatsen van de stations 4. Bij perceeleigenaar (irt weerstand tegen bomenkap) om tafel voor locatiebepaling grondaankoop 5. Indien 1 overblijft wel overgaan naar IBN, 1 onder restwerk scharen | W22: 1. Jarno Sman 2. Jarno Sman 3. Johan van Dronkelaar 4. Jarno Sman 5. Martin Korteschiel | X22: 1.Gereed 2. Gereed. 3. Gereed 4. 3-10-2025 5. 1-7-2026 | AF22: =IFERROR(Tabel2[[#This Row],[Kans ]]*SUM(Tabel2[[#This Row],[Tijd ]:[Omgeving ]]),0) -> 0 | AG22: =VLOOKUP(Tabel2[[#This Row],[Kans ]],KWANTIFICEERTABELLEN!$B$19:$J$26,8,FALSE()) -> 0 | AH22: =IF(F$2<KWANTIFICEERTABELLEN!B$4,VLOOKUP(Tabel2[[#This Row],[Geld ]],KWANTIFICEERTABELLEN!$B$6:$J$13,9,FALSE()), IF(AND(F$2>KWANTIFICEERTABELLEN!B$4,$F$2<KWANTIFICEERTABELLEN!B$30),VLOOKUP(Tabel2[[#This Row],[Geld ]],KWANTIFICEERTABELLEN!$B$19:$J$26,9,FALSE()), IF(F$2>KWANTIFICEERTABELLEN!B$30,VLOOKUP(Tabel2[[#This Row],[Geld ]],KWANTIFICEERTABELLEN!$B$32:$J$39,9,FALSE()),))) -> 0 | AI22: =IFERROR(Tabel2[[#This Row],[Kans ]]*Tabel2[[#This Row],[Rekenwaarde kosten]],0) -> 0 | AJ22: =IF(F$2<KWANTIFICEERTABELLEN!B$4,VLOOKUP(Tabel2[[#This Row],[Tijd ]],KWANTIFICEERTABELLEN!$B$6:$D$13,3,FALSE()), IF(AND(F$2>KWANTIFICEERTABELLEN!B$4,$F$2<KWANTIFICEERTABELLEN!B$30),VLOOKUP(Tabel2[[#This Row],[Tijd ]],KWANTIFICEERTABELLEN!$B$19:$D$26,3,FALSE()), IF(F$2>KWANTIFICEERTABELLEN!B$30,VLOOKUP(Tabel2[[#This Row],[Tijd ]],KWANTIFICEERTABELLEN!$B$32:$D$39,3,FALSE()),))) -> Geen impact
B23: 12 | D23: Bedieningshandelingen zijn niet voldoende meegenomen in de planning | H23: Vervallen | J23: A.Hak | K23: Uitvoering | R23: =IFERROR(Tabel2[[#This Row],[Kans]]*SUM(Tabel2[[#This Row],[Tijd]:[Omgeving]]),0) -> 0 | V23: 1. Indienen van afwijking | W23: 1. Thomas Snoep | X23: 1. Gereed | AF23: =IFERROR(Tabel2[[#This Row],[Kans ]]*SUM(Tabel2[[#This Row],[Tijd ]:[Omgeving ]]),0) -> 0 | AG23: =VLOOKUP(Tabel2[[#This Row],[Kans ]],KWANTIFICEERTABELLEN!$B$19:$J$26,8,FALSE()) -> 0 | AH23: =IF(F$2<KWANTIFICEERTABELLEN!B$4,VLOOKUP(Tabel2[[#This Row],[Geld ]],KWANTIFICEERTABELLEN!$B$6:$J$13,9,FALSE()), IF(AND(F$2>KWANTIFICEERTABELLEN!B$4,$F$2<KWANTIFICEERTABELLEN!B$30),VLOOKUP(Tabel2[[#This Row],[Geld ]],KWANTIFICEERTABELLEN!$B$19:$J$26,9,FALSE()), IF(F$2>KWANTIFICEERTABELLEN!B$30,VLOOKUP(Tabel2[[#This Row],[Geld ]],KWANTIFICEERTABELLEN!$B$32:$J$39,9,FALSE()),))) -> 0 | AI23: =IFERROR(Tabel2[[#This Row],[Kans ]]*Tabel2[[#This Row],[Rekenwaarde kosten]],0) -> 0 | AJ23: =IF(F$2<KWANTIFICEERTABELLEN!B$4,VLOOKUP(Tabel2[[#This Row],[Tijd ]],KWANTIFICEERTABELLEN!$B$6:$D$13,3,FALSE()), IF(AND(F$2>KWANTIFICEERTABELLEN!B$4,$F$2<KWANTIFICEERTABELLEN!B$30),VLOOKUP(Tabel2[[#This Row],[Tijd ]],KWANTIFICEERTABELLEN!$B$19:$D$26,3,FALSE()), IF(F$2>KWANTIFICEERTABELLEN!B$30,VLOOKUP(Tabel2[[#This Row],[Tijd ]],KWANTIFICEERTABELLEN!$B$32:$D$39,3,FALSE()),))) -> Geen impact
B24: 13 | D24: Raakvlak met Gemeente Hollands Kroon is ingrijpender dan verwacht | H24: Vervallen | J24: Bouwteam | K24: Bouwteam | R24: =IFERROR(Tabel2[[#This Row],[Kans]]*SUM(Tabel2[[#This Row],[Tijd]:[Omgeving]]),0) -> 0 | V24: 1. Uitvoeringsplanning afstemmen om te kijken of vanaf tegenovergestelde zijde kan worden gestart met de uitvoering. 2. Onderzoeken of het mogelijk is om gedeeltelijk werkzaamheden uit te voeren om werk te borgen. 3. Voorgaand contact met gemeente onderzoeken op mogelijke raakvlakken. | W24: 1. Thomas Snoep 2. Wouter Duif 3. Peter Joustra | X24: 1. 16-04-2025 2. 09-04-2025 1. 1-05-2025 | AF24: =IFERROR(Tabel2[[#This Row],[Kans ]]*SUM(Tabel2[[#This Row],[Tijd ]:[Omgeving ]]),0) -> 0 | AG24: =VLOOKUP(Tabel2[[#This Row],[Kans ]],KWANTIFICEERTABELLEN!$B$19:$J$26,8,FALSE()) -> 0 | AH24: =IF(F$2<KWANTIFICEERTABELLEN!B$4,VLOOKUP(Tabel2[[#This Row],[Geld ]],KWANTIFICEERTABELLEN!$B$6:$J$13,9,FALSE()), IF(AND(F$2>KWANTIFICEERTABELLEN!B$4,$F$2<KWANTIFICEERTABELLEN!B$30),VLOOKUP(Tabel2[[#This Row],[Geld ]],KWANTIFICEERTABELLEN!$B$19:$J$26,9,FALSE()), IF(F$2>KWANTIFICEERTABELLEN!B$30,VLOOKUP(Tabel2[[#This Row],[Geld ]],KWANTIFICEERTABELLEN!$B$32:$J$39,9,FALSE()),))) -> 0 | AI24: =IFERROR(Tabel2[[#This Row],[Kans ]]*Tabel2[[#This Row],[Rekenwaarde kosten]],0) -> 0 | AJ24: =IF(F$2<KWANTIFICEERTABELLEN!B$4,VLOOKUP(Tabel2[[#This Row],[Tijd ]],KWANTIFICEERTABELLEN!$B$6:$D$13,3,FALSE()), IF(AND(F$2>KWANTIFICEERTABELLEN!B$4,$F$2<KWANTIFICEERTABELLEN!B$30),VLOOKUP(Tabel2[[#This Row],[Tijd ]],KWANTIFICEERTABELLEN!$B$19:$D$26,3,FALSE()), IF(F$2>KWANTIFICEERTABELLEN!B$30,VLOOKUP(Tabel2[[#This Row],[Tijd ]],KWANTIFICEERTABELLEN!$B$32:$D$39,3,FALSE()),))) -> Geen impact
B25: 14 | D25: Gedurende het ZRO proces vinden er nog wijzigingen aan ZR tekeningen plaats. | H25: Vervallen | J25: Bouwteam | K25: Bouwteam | R25: =IFERROR(Tabel2[[#This Row],[Kans]]*SUM(Tabel2[[#This Row],[Tijd]:[Omgeving]]),0) -> 0 | V25: 1. ontwerp van opvolgende (deel)tracés verder te engineeren voor opleveren huidig tracé om wijzigingen in aansluitingen te voorkomen. 2. Via het aanspreekpunt vanuit Techniek sturen op het al verder doorontwerpen van de opvolgende tracés 3. Vastleggen hoe eisen en wensen van stakeholders worden geregistreerd en tussen OM en TM worden gedeeld. 4. Werkinstructie / Proces voor een goedgekeurde design-freeze na tollgate DO op het ontwerp. | AF25: =IFERROR(Tabel2[[#This Row],[Kans ]]*SUM(Tabel2[[#This Row],[Tijd ]:[Omgeving ]]),0) -> 0 | AG25: =VLOOKUP(Tabel2[[#This Row],[Kans ]],KWANTIFICEERTABELLEN!$B$19:$J$26,8,FALSE()) -> 0 | AH25: =IF(F$2<KWANTIFICEERTABELLEN!B$4,VLOOKUP(Tabel2[[#This Row],[Geld ]],KWANTIFICEERTABELLEN!$B$6:$J$13,9,FALSE()), IF(AND(F$2>KWANTIFICEERTABELLEN!B$4,$F$2<KWANTIFICEERTABELLEN!B$30),VLOOKUP(Tabel2[[#This Row],[Geld ]],KWANTIFICEERTABELLEN!$B$19:$J$26,9,FALSE()), IF(F$2>KWANTIFICEERTABELLEN!B$30,VLOOKUP(Tabel2[[#This Row],[Geld ]],KWANTIFICEERTABELLEN!$B$32:$J$39,9,FALSE()),))) -> 0 | AI25: =IFERROR(Tabel2[[#This Row],[Kans ]]*Tabel2[[#This Row],[Rekenwaarde kosten]],0) -> 0 | AJ25: =IF(F$2<KWANTIFICEERTABELLEN!B$4,VLOOKUP(Tabel2[[#This Row],[Tijd ]],KWANTIFICEERTABELLEN!$B$6:$D$13,3,FALSE()), IF(AND(F$2>KWANTIFICEERTABELLEN!B$4,$F$2<KWANTIFICEERTABELLEN!B$30),VLOOKUP(Tabel2[[#This Row],[Tijd ]],KWANTIFICEERTABELLEN!$B$19:$D$26,3,FALSE()), IF(F$2>KWANTIFICEERTABELLEN!B$30,VLOOKUP(Tabel2[[#This Row],[Tijd ]],KWANTIFICEERTABELLEN!$B$32:$D$39,3,FALSE()),))) -> Geen impact
B26: 15 | D26: Gemeente keurt de vergunning niet in een keer goed. | H26: Vervallen | J26: A.Hak | K26: Bouwteam | R26: =IFERROR(Tabel2[[#This Row],[Kans]]*SUM(Tabel2[[#This Row],[Tijd]:[Omgeving]]),0) -> 0 | V26: 1. Vergunning tijdig indienen 2. Overleg met Gemeente om te achterhalen of lange duur procedure vanwege capaciteitsgebrek of afkeur van punten plaatsvind. | W26: 1. Isabel Gheza 2. Isabel Gheza | X26: 1. Gereed 2. Gereed | AF26: =IFERROR(Tabel2[[#This Row],[Kans ]]*SUM(Tabel2[[#This Row],[Tijd ]:[Omgeving ]]),0) -> 0 | AG26: =VLOOKUP(Tabel2[[#This Row],[Kans ]],KWANTIFICEERTABELLEN!$B$19:$J$26,8,FALSE()) -> 0 | AH26: =IF(F$2<KWANTIFICEERTABELLEN!B$4,VLOOKUP(Tabel2[[#This Row],[Geld ]],KWANTIFICEERTABELLEN!$B$6:$J$13,9,FALSE()), IF(AND(F$2>KWANTIFICEERTABELLEN!B$4,$F$2<KWANTIFICEERTABELLEN!B$30),VLOOKUP(Tabel2[[#This Row],[Geld ]],KWANTIFICEERTABELLEN!$B$19:$J$26,9,FALSE()), IF(F$2>KWANTIFICEERTABELLEN!B$30,VLOOKUP(Tabel2[[#This Row],[Geld ]],KWANTIFICEERTABELLEN!$B$32:$J$39,9,FALSE()),))) -> 0 | AI26: =IFERROR(Tabel2[[#This Row],[Kans ]]*Tabel2[[#This Row],[Rekenwaarde kosten]],0) -> 0 | AJ26: =IF(F$2<KWANTIFICEERTABELLEN!B$4,VLOOKUP(Tabel2[[#This Row],[Tijd ]],KWANTIFICEERTABELLEN!$B$6:$D$13,3,FALSE()), IF(AND(F$2>KWANTIFICEERTABELLEN!B$4,$F$2<KWANTIFICEERTABELLEN!B$30),VLOOKUP(Tabel2[[#This Row],[Tijd ]],KWANTIFICEERTABELLEN!$B$19:$D$26,3,FALSE()), IF(F$2>KWANTIFICEERTABELLEN!B$30,VLOOKUP(Tabel2[[#This Row],[Tijd ]],KWANTIFICEERTABELLEN!$B$32:$D$39,3,FALSE()),))) -> Geen impact
B27: 16 | D27: Er is geen gedegen dossieroverdracht vanuit omgeving mogelijk naar G&R | H27: Vervallen | J27: Bouwteam | K27: Bouwteam | R27: =IFERROR(Tabel2[[#This Row],[Kans]]*SUM(Tabel2[[#This Row],[Tijd]:[Omgeving]]),0) -> 0 | AF27: =IFERROR(Tabel2[[#This Row],[Kans ]]*SUM(Tabel2[[#This Row],[Tijd ]:[Omgeving ]]),0) -> 0 | AG27: =VLOOKUP(Tabel2[[#This Row],[Kans ]],KWANTIFICEERTABELLEN!$B$19:$J$26,8,FALSE()) -> 0 | AH27: =IF(F$2<KWANTIFICEERTABELLEN!B$4,VLOOKUP(Tabel2[[#This Row],[Geld ]],KWANTIFICEERTABELLEN!$B$6:$J$13,9,FALSE()), IF(AND(F$2>KWANTIFICEERTABELLEN!B$4,$F$2<KWANTIFICEERTABELLEN!B$30),VLOOKUP(Tabel2[[#This Row],[Geld ]],KWANTIFICEERTABELLEN!$B$19:$J$26,9,FALSE()), IF(F$2>KWANTIFICEERTABELLEN!B$30,VLOOKUP(Tabel2[[#This Row],[Geld ]],KWANTIFICEERTABELLEN!$B$32:$J$39,9,FALSE()),))) -> 0 | AI27: =IFERROR(Tabel2[[#This Row],[Kans ]]*Tabel2[[#This Row],[Rekenwaarde kosten]],0) -> 0 | AJ27: =IF(F$2<KWANTIFICEERTABELLEN!B$4,VLOOKUP(Tabel2[[#This Row],[Tijd ]],KWANTIFICEERTABELLEN!$B$6:$D$13,3,FALSE()), IF(AND(F$2>KWANTIFICEERTABELLEN!B$4,$F$2<KWANTIFICEERTABELLEN!B$30),VLOOKUP(Tabel2[[#This Row],[Tijd ]],KWANTIFICEERTABELLEN!$B$19:$D$26,3,FALSE()), IF(F$2>KWANTIFICEERTABELLEN!B$30,VLOOKUP(Tabel2[[#This Row],[Tijd ]],KWANTIFICEERTABELLEN!$B$32:$D$39,3,FALSE()),))) -> Geen impact
B28: 69 | C28: Beiden | D28: Brandstofprijzen verhoogd | E28: 1. Geopolitieke bewegingen | F28: 1. Hogere kosten voor transport (intern en extern) 2. Hogere kosten HDPE 3. Hogere kosten operatie | H28: Actueel | I28: Onno Cavalini | J28: Liander | K28: Uitvoering | L28: 6 | M28: 5 | N28: 7 | O28: 3 | P28: 0 | Q28: 0 | R28: =IFERROR(Tabel2[[#This Row],[Kans]]*SUM(Tabel2[[#This Row],[Tijd]:[Omgeving]]),0) -> 90 | S28: =IF(F$2<KWANTIFICEERTABELLEN!B$17,_xlfn.XLOOKUP(Tabel2[[#This Row],[Kans]],KWANTIFICEERTABELLEN!$B$6:$B$13,KWANTIFICEERTABELLEN!I$6:I$13,), IF(AND(F$2>KWANTIFICEERTABELLEN!B$17,$F$2<KWANTIFICEERTABELLEN!B$30),_xlfn.XLOOKUP(Tabel2[[#This Row],[Kans]],KWANTIFICEERTABELLEN!$B$19:$B$26,KWANTIFICEERTABELLEN!I$19:I$26), IF(F$2>KWANTIFICEERTABELLEN!B$30,_xlfn.XLOOKUP(Tabel2[[#This Row],[Kans]],KWANTIFICEERTABELLEN!$B$32:$B$39,KWANTIFICEERTABELLEN!I$32:I$39)))) -> 0.5 | V28: 1. Vroegtijdig inkopen | Z28: 5 | AA28: 5 | AB28: 7 | AC28: 3 | AD28: 0 | AE28: 0 | AF28: =IFERROR(Tabel2[[#This Row],[Kans ]]*SUM(Tabel2[[#This Row],[Tijd ]:[Omgeving ]]),0) -> 75 | AG28: =IF(F$2<KWANTIFICEERTABELLEN!B$17,_xlfn.XLOOKUP(Tabel2[[#This Row],[Kans ]],KWANTIFICEERTABELLEN!$B$6:$B$13,KWANTIFICEERTABELLEN!I$6:I$13,), IF(AND(F$2>KWANTIFICEERTABELLEN!B$17,$F$2<KWANTIFICEERTABELLEN!B$30),_xlfn.XLOOKUP(Tabel2[[#This Row],[Kans ]],KWANTIFICEERTABELLEN!$B$19:$B$26,KWANTIFICEERTABELLEN!I$19:I$26), IF(F$2>KWANTIFICEERTABELLEN!B$30,_xlfn.XLOOKUP(Tabel2[[#This Row],[Kans ]],KWANTIFICEERTABELLEN!$B$32:$B$39,KWANTIFICEERTABELLEN!I$32:I$39)))) -> 0.4 | AH28: =IF(F$2<KWANTIFICEERTABELLEN!B$17,_xlfn.XLOOKUP(Tabel2[[#This Row],[Geld ]],KWANTIFICEERTABELLEN!$B$6:$B$13,KWANTIFICEERTABELLEN!J$6:J$13,), IF(AND(F$2>KWANTIFICEERTABELLEN!B$17,$F$2<KWANTIFICEERTABELLEN!B$30),_xlfn.XLOOKUP(Tabel2[[#This Row],[Geld ]],KWANTIFICEERTABELLEN!$B$19:$B$26,KWANTIFICEERTABELLEN!J$19:J$26), IF(F$2>KWANTIFICEERTABELLEN!B$30,_xlfn.XLOOKUP(Tabel2[[#This Row],[Geld ]],KWANTIFICEERTABELLEN!$B$32:$B$39,KWANTIFICEERTABELLEN!J$32:J$39)))) -> 100000 | AI28: =IFERROR(Tabel2[[#This Row],[Kans ]]*Tabel2[[#This Row],[Rekenwaarde kosten]],0) -> 40000 | AJ28: =IF(F$2<KWANTIFICEERTABELLEN!B$4,VLOOKUP(Tabel2[[#This Row],[Tijd ]],KWANTIFICEERTABELLEN!$B$6:$D$13,3,FALSE()), IF(AND(F$2>KWANTIFICEERTABELLEN!B$4,$F$2<KWANTIFICEERTABELLEN!B$30),VLOOKUP(Tabel2[[#This Row],[Tijd ]],KWANTIFICEERTABELLEN!$B$19:$D$26,3,FALSE()), IF(F$2>KWANTIFICEERTABELLEN!B$30,VLOOKUP(Tabel2[[#This Row],[Tijd ]],KWANTIFICEERTABELLEN!$B$32:$D$39,3,FALSE()),))) -> 4 - 6 weken
B29: 18 | D29: Aanpassinging in ontwerp waardoor vergunningen moeten worden aangepast | E29: 1. Voortschrijdend inzicht in de ontwerpeisen leidt tot aanpassingen na indiening van de vergunning; 2. Eisen vanuit OIV'er of bevoegd gezag worden pas laat in het proces duidelijk; 3. Wijzigingen in het tracé of de stationslocaties noodzaken herziening van de reeds ingediende vergunning. | F29: 1. Vergunning moet worden ingetrokken en opnieuw aangevraagd, waardoor de doorlooptijd aanzienlijk toeneemt; 2. Vertraging in de uitvoeringsstart door het opnieuw doorlopen van de vergunningsprocedure; 3. Extra engineeringskosten voor herziening van de vergunningsdocumenten. | G29: Alle tekeningen zijn definitief, OIV'ers zijn akkoord. Alleen nog reactie gemeente, maar is in ander risico geborgd | H29: Vervallen | I29: Isabel Gheza | J29: A.Hak | K29: Bouwteam | L29: 1 | M29: 5 | N29: 2 | O29: 0 | P29: 0 | Q29: 4 | R29: =IFERROR(Tabel2[[#This Row],[Kans]]*SUM(Tabel2[[#This Row],[Tijd]:[Omgeving]]),0) -> 11 | V29: 1. Akkoord OIV'er tijdig aanvragen 2. Aanpassingen tijdig doorgeven bij Gemeente Hollands Kroon | W29: 1. Liander 2. OM | Z29: 1 | AA29: 5 | AB29: 2 | AC29: 0 | AD29: 0 | AE29: 4 | AF29: =IFERROR(Tabel2[[#This Row],[Kans ]]*SUM(Tabel2[[#This Row],[Tijd ]:[Omgeving ]]),0) -> 11 | AG29: =VLOOKUP(Tabel2[[#This Row],[Kans ]],KWANTIFICEERTABELLEN!$B$19:$J$26,8,FALSE()) -> 0.05 | AH29: =IF(F$2<KWANTIFICEERTABELLEN!B$4,VLOOKUP(Tabel2[[#This Row],[Geld ]],KWANTIFICEERTABELLEN!$B$6:$J$13,9,FALSE()), IF(AND(F$2>KWANTIFICEERTABELLEN!B$4,$F$2<KWANTIFICEERTABELLEN!B$30),VLOOKUP(Tabel2[[#This Row],[Geld ]],KWANTIFICEERTABELLEN!$B$19:$J$26,9,FALSE()), IF(F$2>KWANTIFICEERTABELLEN!B$30,VLOOKUP(Tabel2[[#This Row],[Geld ]],KWANTIFICEERTABELLEN!$B$32:$J$39,9,FALSE()),))) -> 7500 | AI29: =IFERROR(Tabel2[[#This Row],[Kans ]]*Tabel2[[#This Row],[Rekenwaarde kosten]],0) -> 375 | AJ29: =IF(F$2<KWANTIFICEERTABELLEN!B$4,VLOOKUP(Tabel2[[#This Row],[Tijd ]],KWANTIFICEERTABELLEN!$B$6:$D$13,3,FALSE()), IF(AND(F$2>KWANTIFICEERTABELLEN!B$4,$F$2<KWANTIFICEERTABELLEN!B$30),VLOOKUP(Tabel2[[#This Row],[Tijd ]],KWANTIFICEERTABELLEN!$B$19:$D$26,3,FALSE()), IF(F$2>KWANTIFICEERTABELLEN!B$30,VLOOKUP(Tabel2[[#This Row],[Tijd ]],KWANTIFICEERTABELLEN!$B$32:$D$39,3,FALSE()),))) -> 4 - 6 weken
B30: 91 | C30: DP1 (Hoofdtracé) | D30: Er wordt bodemvervuiling aangetroffen (anders dan in de onderzoeken) | E30: 1. Onvolledig of beperkt bodemonderzoek (steekproefsgewijs, andere dieptes of zones dan het werkgebied); 2. Historische activiteiten of calamiteiten die niet bekend of gedocumenteerd zijn; 3. Afwijkingen in de uitvoering (dieper graven of grotere verstoring dan onderzocht). | F30: 1. Stillegging van werkzaamheden totdat aard en omvang van de vervuiling zijn vastgesteld; 2. Extra kosten en vertraging door aanvullend onderzoek, sanering of aangepaste uitvoering; 3. Gezondheids- en milieurisico's bij blootstelling van personeel of verspreiding van de verontreiniging. | H30: Voorstel | I30: Onno Cavalini | J30: Liander | K30: Uitvoering | R30: =IFERROR(Tabel2[[#This Row],[Kans]]*SUM(Tabel2[[#This Row],[Tijd]:[Omgeving]]),0) -> 0 | S30: =IF(F$2<KWANTIFICEERTABELLEN!B$17,_xlfn.XLOOKUP(Tabel2[[#This Row],[Kans]],KWANTIFICEERTABELLEN!$B$6:$B$13,KWANTIFICEERTABELLEN!I$6:I$13,), IF(AND(F$2>KWANTIFICEERTABELLEN!B$17,$F$2<KWANTIFICEERTABELLEN!B$30),_xlfn.XLOOKUP(Tabel2[[#This Row],[Kans]],KWANTIFICEERTABELLEN!$B$19:$B$26,KWANTIFICEERTABELLEN!I$19:I$26), IF(F$2>KWANTIFICEERTABELLEN!B$30,_xlfn.XLOOKUP(Tabel2[[#This Row],[Kans]],KWANTIFICEERTABELLEN!$B$32:$B$39,KWANTIFICEERTABELLEN!I$32:I$39)))) -> #N/A | V30: 1. Bodemonderzoek kritisch toetsen op representativiteit voor het volledige werkgebied en de werkdiepte; 2. Bodemrisico's expliciet opnemen in werkplannen en V&G-plan; 3. Instructie aan uitvoerend personeel over herkennen en melden van verdachte bodem. | Z30: 3 | AA30: 5 | AB30: 5 | AC30: 4 | AD30: 4 | AE30: 5 | AF30: =IFERROR(Tabel2[[#This Row],[Kans ]]*SUM(Tabel2[[#This Row],[Tijd ]:[Omgeving ]]),0) -> 69 | AG30: =IF(F$2<KWANTIFICEERTABELLEN!B$17,_xlfn.XLOOKUP(Tabel2[[#This Row],[Kans ]],KWANTIFICEERTABELLEN!$B$6:$B$13,KWANTIFICEERTABELLEN!I$6:I$13,), IF(AND(F$2>KWANTIFICEERTABELLEN!B$17,$F$2<KWANTIFICEERTABELLEN!B$30),_xlfn.XLOOKUP(Tabel2[[#This Row],[Kans ]],KWANTIFICEERTABELLEN!$B$19:$B$26,KWANTIFICEERTABELLEN!I$19:I$26), IF(F$2>KWANTIFICEERTABELLEN!B$30,_xlfn.XLOOKUP(Tabel2[[#This Row],[Kans ]],KWANTIFICEERTABELLEN!$B$32:$B$39,KWANTIFICEERTABELLEN!I$32:I$39)))) -> 0.2 | AH30: =IF(F$2<KWANTIFICEERTABELLEN!B$17,_xlfn.XLOOKUP(Tabel2[[#This Row],[Geld ]],KWANTIFICEERTABELLEN!$B$6:$B$13,KWANTIFICEERTABELLEN!J$6:J$13,), IF(AND(F$2>KWANTIFICEERTABELLEN!B$17,$F$2<KWANTIFICEERTABELLEN!B$30),_xlfn.XLOOKUP(Tabel2[[#This Row],[Geld ]],KWANTIFICEERTABELLEN!$B$19:$B$26,KWANTIFICEERTABELLEN!J$19:J$26), IF(F$2>KWANTIFICEERTABELLEN!B$30,_xlfn.XLOOKUP(Tabel2[[#This Row],[Geld ]],KWANTIFICEERTABELLEN!$B$32:$B$39,KWANTIFICEERTABELLEN!J$32:J$39)))) -> 67500 | AI30: =IFERROR(Tabel2[[#This Row],[Kans ]]*Tabel2[[#This Row],[Rekenwaarde kosten]],0) -> 13500 | AJ30: =IF(F$2<KWANTIFICEERTABELLEN!B$4,VLOOKUP(Tabel2[[#This Row],[Tijd ]],KWANTIFICEERTABELLEN!$B$6:$D$13,3,FALSE()), IF(AND(F$2>KWANTIFICEERTABELLEN!B$4,$F$2<KWANTIFICEERTABELLEN!B$30),VLOOKUP(Tabel2[[#This Row],[Tijd ]],KWANTIFICEERTABELLEN!$B$19:$D$26,3,FALSE()), IF(F$2>KWANTIFICEERTABELLEN!B$30,VLOOKUP(Tabel2[[#This Row],[Tijd ]],KWANTIFICEERTABELLEN!$B$32:$D$39,3,FALSE()),))) -> 4 - 6 weken
B31: 2 | C31: DP1 (Hoofdtracé) | D31: Levering van MSR (14 stuks nieuw en 2 stuks vervangen) vindt niet conform planning plaats. | E31: 1. Kwaliteit is door de leverancier niet geborgd); 2. Door stijging van de vraag naar MSR's is de leveringscapaciteit bij de leverancier onvoldoende; 3. Langere lead-times door schaarste aan componenten of productieproblemen bij de fabrikant. | F31: 1. Project kan niet conform planning worden afgerond doordat stations ontbreken; 2. IBN datum wordt niet gehaald, met risico op contractuele boetes; 3. Uitvoering kan niet starten of wordt stilgelegd, met extra kosten als gevolg. | H31: Vervallen | I31: Aldo de Bock | J31: Bouwteam | K31: Uitvoering | R31: =IFERROR(Tabel2[[#This Row],[Kans]]*SUM(Tabel2[[#This Row],[Tijd]:[Omgeving]]),0) -> 0 | V31: 1. Elke week met inkoop dit onderwerp bespreken 2. Bij start project (nadat technische details bekend zijn) MSR bestellen 3. Bij een andere leverancier MSR inkopen (AKA is de leverancier) | W31: 1. TM 2. TM 3. TM | X31: Gereed | Y31: Opmerking ABO 27-05-2026: De stations zijn allemaal gefabriceerd en staan klaar bij de leverancier. Ik denk dat dit risico kan komen te vervallen. | Z31: 6 | AA31: 6 | AB31: 4 | AC31: 0 | AD31: 0 | AE31: 0 | AF31: =IFERROR(Tabel2[[#This Row],[Kans ]]*SUM(Tabel2[[#This Row],[Tijd ]:[Omgeving ]]),0) -> 60 | AG31: =VLOOKUP(Tabel2[[#This Row],[Kans ]],KWANTIFICEERTABELLEN!$B$19:$J$26,8,FALSE()) -> 0.5 | AH31: =IF(F$2<KWANTIFICEERTABELLEN!B$4,VLOOKUP(Tabel2[[#This Row],[Geld ]],KWANTIFICEERTABELLEN!$B$6:$J$13,9,FALSE()), IF(AND(F$2>KWANTIFICEERTABELLEN!B$4,$F$2<KWANTIFICEERTABELLEN!B$30),VLOOKUP(Tabel2[[#This Row],[Geld ]],KWANTIFICEERTABELLEN!$B$19:$J$26,9,FALSE()), IF(F$2>KWANTIFICEERTABELLEN!B$30,VLOOKUP(Tabel2[[#This Row],[Geld ]],KWANTIFICEERTABELLEN!$B$32:$J$39,9,FALSE()),))) -> 37500 | AI31: =IFERROR(Tabel2[[#This Row],[Kans ]]*Tabel2[[#This Row],[Rekenwaarde kosten]],0) -> 18750 | AJ31: =IF(F$2<KWANTIFICEERTABELLEN!B$4,VLOOKUP(Tabel2[[#This Row],[Tijd ]],KWANTIFICEERTABELLEN!$B$6:$D$13,3,FALSE()), IF(AND(F$2>KWANTIFICEERTABELLEN!B$4,$F$2<KWANTIFICEERTABELLEN!B$30),VLOOKUP(Tabel2[[#This Row],[Tijd ]],KWANTIFICEERTABELLEN!$B$19:$D$26,3,FALSE()), IF(F$2>KWANTIFICEERTABELLEN!B$30,VLOOKUP(Tabel2[[#This Row],[Tijd ]],KWANTIFICEERTABELLEN!$B$32:$D$39,3,FALSE()),))) -> 6 - 8 weken
B32: 87 | C32: DP1 (Hoofdtracé) | D32: Overlast werkzaamheden voor omwonenden/perceeleigenaren tijdens de uitvoering (10 kV) | E32: 1. Onvoldoende of te late communicatie richting omwonenden over aard, planning en impact van de werkzaamheden; 2. Afwijkingen van eerder gecommuniceerde afspraken of planning, waardoor vertrouwen afneemt; 3. Ervaren hinder (geluid, bereikbaarheid, trillingen) groter dan verwacht door omwonenden. | F32: 1. Klachten en escalaties richting opdrachtgever, gemeente of bevoegd gezag; 2. Vertraging of tijdelijke stillegging van werkzaamheden door druk vanuit de omgeving; 3. Extra kosten door aanvullende maatregelen, omgevingsafstemming of herplanning. | G32: Risico projectoverstijgend en later opnemen in perceelrisicodossier | H32: Vigerend | I32: Isabel Gheza | J32: Liander | K32: Uitvoering | L32: 6 | M32: 2 | N32: 2 | O32: 2 | P32: 0 | Q32: 4 | R32: =IFERROR(Tabel2[[#This Row],[Kans]]*SUM(Tabel2[[#This Row],[Tijd]:[Omgeving]]),0) -> 60 | S32: =IF(F$2<KWANTIFICEERTABELLEN!B$17,_xlfn.XLOOKUP(Tabel2[[#This Row],[Kans]],KWANTIFICEERTABELLEN!$B$6:$B$13,KWANTIFICEERTABELLEN!I$6:I$13,), IF(AND(F$2>KWANTIFICEERTABELLEN!B$17,$F$2<KWANTIFICEERTABELLEN!B$30),_xlfn.XLOOKUP(Tabel2[[#This Row],[Kans]],KWANTIFICEERTABELLEN!$B$19:$B$26,KWANTIFICEERTABELLEN!I$19:I$26), IF(F$2>KWANTIFICEERTABELLEN!B$30,_xlfn.XLOOKUP(Tabel2[[#This Row],[Kans]],KWANTIFICEERTABELLEN!$B$32:$B$39,KWANTIFICEERTABELLEN!I$32:I$39)))) -> 0.5 | V32: 1. Zes weken voor start uitvoering omwonenden informeren 2. In de Bouwapp goed de updates bijhouden 3. OM'er bereikbaar zijn voor vragen | W32: 1. OM Uitvoering 2. OM Uitvoering | X32: 1. Moet nog vastgesteld worden hoe dit ingevuld wordt | Z32: 5 | AA32: 1 | AB32: 3 | AC32: 5 | AD32: 0 | AE32: 3 | AF32: =IFERROR(Tabel2[[#This Row],[Kans ]]*SUM(Tabel2[[#This Row],[Tijd ]:[Omgeving ]]),0) -> 60 | AG32: =IF(F$2<KWANTIFICEERTABELLEN!B$17,_xlfn.XLOOKUP(Tabel2[[#This Row],[Kans ]],KWANTIFICEERTABELLEN!$B$6:$B$13,KWANTIFICEERTABELLEN!I$6:I$13,), IF(AND(F$2>KWANTIFICEERTABELLEN!B$17,$F$2<KWANTIFICEERTABELLEN!B$30),_xlfn.XLOOKUP(Tabel2[[#This Row],[Kans ]],KWANTIFICEERTABELLEN!$B$19:$B$26,KWANTIFICEERTABELLEN!I$19:I$26), IF(F$2>KWANTIFICEERTABELLEN!B$30,_xlfn.XLOOKUP(Tabel2[[#This Row],[Kans ]],KWANTIFICEERTABELLEN!$B$32:$B$39,KWANTIFICEERTABELLEN!I$32:I$39)))) -> 0.4 | AH32: =IF(F$2<KWANTIFICEERTABELLEN!B$17,_xlfn.XLOOKUP(Tabel2[[#This Row],[Geld ]],KWANTIFICEERTABELLEN!$B$6:$B$13,KWANTIFICEERTABELLEN!J$6:J$13,), IF(AND(F$2>KWANTIFICEERTABELLEN!B$17,$F$2<KWANTIFICEERTABELLEN!B$30),_xlfn.XLOOKUP(Tabel2[[#This Row],[Geld ]],KWANTIFICEERTABELLEN!$B$19:$B$26,KWANTIFICEERTABELLEN!J$19:J$26), IF(F$2>KWANTIFICEERTABELLEN!B$30,_xlfn.XLOOKUP(Tabel2[[#This Row],[Geld ]],KWANTIFICEERTABELLEN!$B$32:$B$39,KWANTIFICEERTABELLEN!J$32:J$39)))) -> 17500 | AI32: =IFERROR(Tabel2[[#This Row],[Kans ]]*Tabel2[[#This Row],[Rekenwaarde kosten]],0) -> 7000 | AJ32: =IF(F$2<KWANTIFICEERTABELLEN!B$4,VLOOKUP(Tabel2[[#This Row],[Tijd ]],KWANTIFICEERTABELLEN!$B$6:$D$13,3,FALSE()), IF(AND(F$2>KWANTIFICEERTABELLEN!B$4,$F$2<KWANTIFICEERTABELLEN!B$30),VLOOKUP(Tabel2[[#This Row],[Tijd ]],KWANTIFICEERTABELLEN!$B$19:$D$26,3,FALSE()), IF(F$2>KWANTIFICEERTABELLEN!B$30,VLOOKUP(Tabel2[[#This Row],[Tijd ]],KWANTIFICEERTABELLEN!$B$32:$D$39,3,FALSE()),))) -> < 0.5 week
B33: 22 | D33: De vergunning voor het grond ontwateren wordt niet verleend om te kunnen starten met de uitvoering | H33: Vervallen | J33: Bouwteam | K33: Bouwteam | R33: =IFERROR(Tabel2[[#This Row],[Kans]]*SUM(Tabel2[[#This Row],[Tijd]:[Omgeving]]),0) -> 0 | V33: 1. Vergunning tijdig indienen | W33: 1. Isabel Gheza | X33: 1. Gereed | AF33: =IFERROR(Tabel2[[#This Row],[Kans ]]*SUM(Tabel2[[#This Row],[Tijd ]:[Omgeving ]]),0) -> 0 | AG33: =VLOOKUP(Tabel2[[#This Row],[Kans ]],KWANTIFICEERTABELLEN!$B$19:$J$26,8,FALSE()) -> 0 | AH33: =IF(F$2<KWANTIFICEERTABELLEN!B$4,VLOOKUP(Tabel2[[#This Row],[Geld ]],KWANTIFICEERTABELLEN!$B$6:$J$13,9,FALSE()), IF(AND(F$2>KWANTIFICEERTABELLEN!B$4,$F$2<KWANTIFICEERTABELLEN!B$30),VLOOKUP(Tabel2[[#This Row],[Geld ]],KWANTIFICEERTABELLEN!$B$19:$J$26,9,FALSE()), IF(F$2>KWANTIFICEERTABELLEN!B$30,VLOOKUP(Tabel2[[#This Row],[Geld ]],KWANTIFICEERTABELLEN!$B$32:$J$39,9,FALSE()),))) -> 0 | AI33: =IFERROR(Tabel2[[#This Row],[Kans ]]*Tabel2[[#This Row],[Rekenwaarde kosten]],0) -> 0 | AJ33: =IF(F$2<KWANTIFICEERTABELLEN!B$4,VLOOKUP(Tabel2[[#This Row],[Tijd ]],KWANTIFICEERTABELLEN!$B$6:$D$13,3,FALSE()), IF(AND(F$2>KWANTIFICEERTABELLEN!B$4,$F$2<KWANTIFICEERTABELLEN!B$30),VLOOKUP(Tabel2[[#This Row],[Tijd ]],KWANTIFICEERTABELLEN!$B$19:$D$26,3,FALSE()), IF(F$2>KWANTIFICEERTABELLEN!B$30,VLOOKUP(Tabel2[[#This Row],[Tijd ]],KWANTIFICEERTABELLEN!$B$32:$D$39,3,FALSE()),))) -> Geen impact
B34: 23 | D34: De vergunning voor het leggen, verleggen, vervangen of repareren van de kabel ten behoeve aan bodemverontreiniging wordt niet verleend voor het kunnen starten met de uitvoering | H34: Vervallen | J34: Bouwteam | K34: Bouwteam | R34: =IFERROR(Tabel2[[#This Row],[Kans]]*SUM(Tabel2[[#This Row],[Tijd]:[Omgeving]]),0) -> 0 | V34: 1. Controleren of melding 4 weken van te voren door movares bodem wordt gemaakt | W34: 1. Isabel | AF34: =IFERROR(Tabel2[[#This Row],[Kans ]]*SUM(Tabel2[[#This Row],[Tijd ]:[Omgeving ]]),0) -> 0 | AG34: =VLOOKUP(Tabel2[[#This Row],[Kans ]],KWANTIFICEERTABELLEN!$B$19:$J$26,8,FALSE()) -> 0 | AH34: =IF(F$2<KWANTIFICEERTABELLEN!B$4,VLOOKUP(Tabel2[[#This Row],[Geld ]],KWANTIFICEERTABELLEN!$B$6:$J$13,9,FALSE()), IF(AND(F$2>KWANTIFICEERTABELLEN!B$4,$F$2<KWANTIFICEERTABELLEN!B$30),VLOOKUP(Tabel2[[#This Row],[Geld ]],KWANTIFICEERTABELLEN!$B$19:$J$26,9,FALSE()), IF(F$2>KWANTIFICEERTABELLEN!B$30,VLOOKUP(Tabel2[[#This Row],[Geld ]],KWANTIFICEERTABELLEN!$B$32:$J$39,9,FALSE()),))) -> 0 | AI34: =IFERROR(Tabel2[[#This Row],[Kans ]]*Tabel2[[#This Row],[Rekenwaarde kosten]],0) -> 0 | AJ34: =IF(F$2<KWANTIFICEERTABELLEN!B$4,VLOOKUP(Tabel2[[#This Row],[Tijd ]],KWANTIFICEERTABELLEN!$B$6:$D$13,3,FALSE()), IF(AND(F$2>KWANTIFICEERTABELLEN!B$4,$F$2<KWANTIFICEERTABELLEN!B$30),VLOOKUP(Tabel2[[#This Row],[Tijd ]],KWANTIFICEERTABELLEN!$B$19:$D$26,3,FALSE()), IF(F$2>KWANTIFICEERTABELLEN!B$30,VLOOKUP(Tabel2[[#This Row],[Tijd ]],KWANTIFICEERTABELLEN!$B$32:$D$39,3,FALSE()),))) -> Geen impact
B35: 24 | D35: De vergunning voor het aanleggen/veranderen van de uitrit is niet verkregen om te kunnen starten met de uitvoering bij de slootweg | E35: 1. Vergunningsaanvraag niet tijdig ingediend of gemeente stelt aanvullende eisen aan de uitrit; 2. Perceeleigenaar werkt niet mee aan het aanvraagproces; 3. Technische beoordeling door gemeente leidt tot aanpassingsvereisten. | F35: 1. Uitvoering bij de slootweg kan niet starten door het ontbreken van de benodigde vergunning; 2. Vertraging in de uitvoering van de aangrenzende tracédelen; 3. Extra kosten door herplanning of aanpassing van de aanvoerroute. | H35: Vervallen | I35: Isabel Gheza | J35: Bouwteam | K35: Bouwteam | R35: =IFERROR(Tabel2[[#This Row],[Kans]]*SUM(Tabel2[[#This Row],[Tijd]:[Omgeving]]),0) -> 0 | V35: 1. Rechtstreeks benaderen voor vergunning parallel aan de gesprekken met de rentmeesters indien niet voor 17-10-2025 wordt getekend. Vergunning kan verleend worden eind januari | W35: 1 Isabel Gheza | X35: 1. Gereed | Z35: 2 | AA35: 4 | AB35: 2 | AC35: 1 | AD35: 0 | AE35: 1 | AF35: =IFERROR(Tabel2[[#This Row],[Kans ]]*SUM(Tabel2[[#This Row],[Tijd ]:[Omgeving ]]),0) -> 16 | AG35: =VLOOKUP(Tabel2[[#This Row],[Kans ]],KWANTIFICEERTABELLEN!$B$19:$J$26,8,FALSE()) -> 0.1 | AH35: =IF(F$2<KWANTIFICEERTABELLEN!B$4,VLOOKUP(Tabel2[[#This Row],[Geld ]],KWANTIFICEERTABELLEN!$B$6:$J$13,9,FALSE()), IF(AND(F$2>KWANTIFICEERTABELLEN!B$4,$F$2<KWANTIFICEERTABELLEN!B$30),VLOOKUP(Tabel2[[#This Row],[Geld ]],KWANTIFICEERTABELLEN!$B$19:$J$26,9,FALSE()), IF(F$2>KWANTIFICEERTABELLEN!B$30,VLOOKUP(Tabel2[[#This Row],[Geld ]],KWANTIFICEERTABELLEN!$B$32:$J$39,9,FALSE()),))) -> 7500 | AI35: =IFERROR(Tabel2[[#This Row],[Kans ]]*Tabel2[[#This Row],[Rekenwaarde kosten]],0) -> 750 | AJ35: =IF(F$2<KWANTIFICEERTABELLEN!B$4,VLOOKUP(Tabel2[[#This Row],[Tijd ]],KWANTIFICEERTABELLEN!$B$6:$D$13,3,FALSE()), IF(AND(F$2>KWANTIFICEERTABELLEN!B$4,$F$2<KWANTIFICEERTABELLEN!B$30),VLOOKUP(Tabel2[[#This Row],[Tijd ]],KWANTIFICEERTABELLEN!$B$19:$D$26,3,FALSE()), IF(F$2>KWANTIFICEERTABELLEN!B$30,VLOOKUP(Tabel2[[#This Row],[Tijd ]],KWANTIFICEERTABELLEN!$B$32:$D$39,3,FALSE()),))) -> 2 - 4 weken
B36: 25 | D36: De vergunning omtrent activiteit aan de dam of duiker is niet op tijd verkregen om met de uitvoering te kunnen starten | H36: vervallen | J36: Bouwteam | K36: Bouwteam | R36: =IFERROR(Tabel2[[#This Row],[Kans]]*SUM(Tabel2[[#This Row],[Tijd]:[Omgeving]]),0) -> 0 | AF36: =IFERROR(Tabel2[[#This Row],[Kans ]]*SUM(Tabel2[[#This Row],[Tijd ]:[Omgeving ]]),0) -> 0 | AG36: =VLOOKUP(Tabel2[[#This Row],[Kans ]],KWANTIFICEERTABELLEN!$B$19:$J$26,8,FALSE()) -> 0 | AH36: =IF(F$2<KWANTIFICEERTABELLEN!B$4,VLOOKUP(Tabel2[[#This Row],[Geld ]],KWANTIFICEERTABELLEN!$B$6:$J$13,9,FALSE()), IF(AND(F$2>KWANTIFICEERTABELLEN!B$4,$F$2<KWANTIFICEERTABELLEN!B$30),VLOOKUP(Tabel2[[#This Row],[Geld ]],KWANTIFICEERTABELLEN!$B$19:$J$26,9,FALSE()), IF(F$2>KWANTIFICEERTABELLEN!B$30,VLOOKUP(Tabel2[[#This Row],[Geld ]],KWANTIFICEERTABELLEN!$B$32:$J$39,9,FALSE()),))) -> 0 | AI36: =IFERROR(Tabel2[[#This Row],[Kans ]]*Tabel2[[#This Row],[Rekenwaarde kosten]],0) -> 0 | AJ36: =IF(F$2<KWANTIFICEERTABELLEN!B$4,VLOOKUP(Tabel2[[#This Row],[Tijd ]],KWANTIFICEERTABELLEN!$B$6:$D$13,3,FALSE()), IF(AND(F$2>KWANTIFICEERTABELLEN!B$4,$F$2<KWANTIFICEERTABELLEN!B$30),VLOOKUP(Tabel2[[#This Row],[Tijd ]],KWANTIFICEERTABELLEN!$B$19:$D$26,3,FALSE()), IF(F$2>KWANTIFICEERTABELLEN!B$30,VLOOKUP(Tabel2[[#This Row],[Tijd ]],KWANTIFICEERTABELLEN!$B$32:$D$39,3,FALSE()),))) -> Geen impact
B37: 26 | D37: De vergunning rondom activiteit van Flora en Fauna is niet op tijd verkregen om te kunnen starten met de uitvoering | H37: Vervallen | J37: Bouwteam | K37: Bouwteam | R37: =IFERROR(Tabel2[[#This Row],[Kans]]*SUM(Tabel2[[#This Row],[Tijd]:[Omgeving]]),0) -> 0 | AF37: =IFERROR(Tabel2[[#This Row],[Kans ]]*SUM(Tabel2[[#This Row],[Tijd ]:[Omgeving ]]),0) -> 0 | AG37: =VLOOKUP(Tabel2[[#This Row],[Kans ]],KWANTIFICEERTABELLEN!$B$19:$J$26,8,FALSE()) -> 0 | AH37: =IF(F$2<KWANTIFICEERTABELLEN!B$4,VLOOKUP(Tabel2[[#This Row],[Geld ]],KWANTIFICEERTABELLEN!$B$6:$J$13,9,FALSE()), IF(AND(F$2>KWANTIFICEERTABELLEN!B$4,$F$2<KWANTIFICEERTABELLEN!B$30),VLOOKUP(Tabel2[[#This Row],[Geld ]],KWANTIFICEERTABELLEN!$B$19:$J$26,9,FALSE()), IF(F$2>KWANTIFICEERTABELLEN!B$30,VLOOKUP(Tabel2[[#This Row],[Geld ]],KWANTIFICEERTABELLEN!$B$32:$J$39,9,FALSE()),))) -> 0 | AI37: =IFERROR(Tabel2[[#This Row],[Kans ]]*Tabel2[[#This Row],[Rekenwaarde kosten]],0) -> 0 | AJ37: =IF(F$2<KWANTIFICEERTABELLEN!B$4,VLOOKUP(Tabel2[[#This Row],[Tijd ]],KWANTIFICEERTABELLEN!$B$6:$D$13,3,FALSE()), IF(AND(F$2>KWANTIFICEERTABELLEN!B$4,$F$2<KWANTIFICEERTABELLEN!B$30),VLOOKUP(Tabel2[[#This Row],[Tijd ]],KWANTIFICEERTABELLEN!$B$19:$D$26,3,FALSE()), IF(F$2>KWANTIFICEERTABELLEN!B$30,VLOOKUP(Tabel2[[#This Row],[Tijd ]],KWANTIFICEERTABELLEN!$B$32:$D$39,3,FALSE()),))) -> Geen impact
B38: 27 | D38: De omgevingsvergunning rondom de provinciale weg is niet verkregen om te kunnen starten met de uitvoering | E38: 1. Provincie Noord-Holland stelt aanvullende eisen aan het intredepunt of de uitvoeringsmethode; 2. Het tracé of intredepunt sluit niet aan bij de eisen van de provincie; 3. Vergunningsaanvraag onvolledig of niet tijdig ingediend. | F38: 1. Werkzaamheden nabij de provinciale weg kunnen niet worden uitgevoerd; 2. Herontwerp van het intredepunt of het tracé is noodzakelijk, met extra engineeringskosten; 3. Vertraging in de uitvoering doordat de vergunningsprocedure opnieuw moet worden doorlopen. | H38: Vervallen | I38: Isabel Gheza | J38: Bouwteam | K38: Bouwteam | R38: =IFERROR(Tabel2[[#This Row],[Kans]]*SUM(Tabel2[[#This Row],[Tijd]:[Omgeving]]),0) -> 0 | V38: 1. Onderbouwde toelichting waarom intredepunt op de geschetste locatie moet. 2. Alternatieven uitwerken 3. Gekozen alternatief neerleggen bij Provincie Noord-Holland | W38: 1. Isabel Gheza 2. Reimer Lap 3. Isabel Gheza | X38: 1. Gereed 2. 21-11-2025 3. Open | Z38: 2 | AA38: 5 | AB38: 3 | AC38: 3 | AD38: 0 | AE38: 0 | AF38: =IFERROR(Tabel2[[#This Row],[Kans ]]*SUM(Tabel2[[#This Row],[Tijd ]:[Omgeving ]]),0) -> 22 | AG38: =VLOOKUP(Tabel2[[#This Row],[Kans ]],KWANTIFICEERTABELLEN!$B$19:$J$26,8,FALSE()) -> 0.1 | AH38: =IF(F$2<KWANTIFICEERTABELLEN!B$4,VLOOKUP(Tabel2[[#This Row],[Geld ]],KWANTIFICEERTABELLEN!$B$6:$J$13,9,FALSE()), IF(AND(F$2>KWANTIFICEERTABELLEN!B$4,$F$2<KWANTIFICEERTABELLEN!B$30),VLOOKUP(Tabel2[[#This Row],[Geld ]],KWANTIFICEERTABELLEN!$B$19:$J$26,9,FALSE()), IF(F$2>KWANTIFICEERTABELLEN!B$30,VLOOKUP(Tabel2[[#This Row],[Geld ]],KWANTIFICEERTABELLEN!$B$32:$J$39,9,FALSE()),))) -> 17500 | AI38: =IFERROR(Tabel2[[#This Row],[Kans ]]*Tabel2[[#This Row],[Rekenwaarde kosten]],0) -> 1750 | AJ38: =IF(F$2<KWANTIFICEERTABELLEN!B$4,VLOOKUP(Tabel2[[#This Row],[Tijd ]],KWANTIFICEERTABELLEN!$B$6:$D$13,3,FALSE()), IF(AND(F$2>KWANTIFICEERTABELLEN!B$4,$F$2<KWANTIFICEERTABELLEN!B$30),VLOOKUP(Tabel2[[#This Row],[Tijd ]],KWANTIFICEERTABELLEN!$B$19:$D$26,3,FALSE()), IF(F$2>KWANTIFICEERTABELLEN!B$30,VLOOKUP(Tabel2[[#This Row],[Tijd ]],KWANTIFICEERTABELLEN!$B$32:$D$39,3,FALSE()),))) -> 4 - 6 weken
B39: 28 | D39: De grondaankoop voor MSR-12 is niet tijdig verkregen waardoor het station niet kan worden geplaatst | H39: Vervallen | J39: Liander | K39: Uitvoering | R39: =IFERROR(Tabel2[[#This Row],[Kans]]*SUM(Tabel2[[#This Row],[Tijd]:[Omgeving]]),0) -> 0 | V39: 1. Gesprekken lopen bij grond en recht, voorlopig status monitoren of weerstand wordt ervaren gedurende de gesprekken | W39: 1. Jarno Sman | X39: 1. 10-12-2025 | AF39: =IFERROR(Tabel2[[#This Row],[Kans ]]*SUM(Tabel2[[#This Row],[Tijd ]:[Omgeving ]]),0) -> 0 | AG39: =VLOOKUP(Tabel2[[#This Row],[Kans ]],KWANTIFICEERTABELLEN!$B$19:$J$26,8,FALSE()) -> 0 | AH39: =IF(F$2<KWANTIFICEERTABELLEN!B$4,VLOOKUP(Tabel2[[#This Row],[Geld ]],KWANTIFICEERTABELLEN!$B$6:$J$13,9,FALSE()), IF(AND(F$2>KWANTIFICEERTABELLEN!B$4,$F$2<KWANTIFICEERTABELLEN!B$30),VLOOKUP(Tabel2[[#This Row],[Geld ]],KWANTIFICEERTABELLEN!$B$19:$J$26,9,FALSE()), IF(F$2>KWANTIFICEERTABELLEN!B$30,VLOOKUP(Tabel2[[#This Row],[Geld ]],KWANTIFICEERTABELLEN!$B$32:$J$39,9,FALSE()),))) -> 0 | AI39: =IFERROR(Tabel2[[#This Row],[Kans ]]*Tabel2[[#This Row],[Rekenwaarde kosten]],0) -> 0 | AJ39: =IF(F$2<KWANTIFICEERTABELLEN!B$4,VLOOKUP(Tabel2[[#This Row],[Tijd ]],KWANTIFICEERTABELLEN!$B$6:$D$13,3,FALSE()), IF(AND(F$2>KWANTIFICEERTABELLEN!B$4,$F$2<KWANTIFICEERTABELLEN!B$30),VLOOKUP(Tabel2[[#This Row],[Tijd ]],KWANTIFICEERTABELLEN!$B$19:$D$26,3,FALSE()), IF(F$2>KWANTIFICEERTABELLEN!B$30,VLOOKUP(Tabel2[[#This Row],[Tijd ]],KWANTIFICEERTABELLEN!$B$32:$D$39,3,FALSE()),))) -> Geen impact
B40: 29 | D40: De grondaankoop voor MSR-3 is niet tijdig verkregen waardoor het station niet kan worden geplaatst | E40: 1. ZRO proces niet goed doorlopen | F40: 1. Niet kunnen plaatsen MSR 2. Net niet overnemen 3. IBN datum verschuift | H40: Vervallen | I40: Isabel Gheza | J40: Liander | K40: Uitvoering | L40: 5 | M40: 7 | N40: 2 | O40: 7 | P40: 0 | Q40: 4 | R40: =IFERROR(Tabel2[[#This Row],[Kans]]*SUM(Tabel2[[#This Row],[Tijd]:[Omgeving]]),0) -> 100 | S40: =IF(F$2<KWANTIFICEERTABELLEN!B$17,_xlfn.XLOOKUP(Tabel2[[#This Row],[Kans]],KWANTIFICEERTABELLEN!$B$6:$B$13,KWANTIFICEERTABELLEN!I$6:I$13,), IF(AND(F$2>KWANTIFICEERTABELLEN!B$17,$F$2<KWANTIFICEERTABELLEN!B$30),_xlfn.XLOOKUP(Tabel2[[#This Row],[Kans]],KWANTIFICEERTABELLEN!$B$19:$B$26,KWANTIFICEERTABELLEN!I$19:I$26), IF(F$2>KWANTIFICEERTABELLEN!B$30,_xlfn.XLOOKUP(Tabel2[[#This Row],[Kans]],KWANTIFICEERTABELLEN!$B$32:$B$39,KWANTIFICEERTABELLEN!I$32:I$39)))) -> 0.4 | V40: 1. Jurist inschakelen, koerst uitzetten naar gedogen. Er komt nog een finale aanbieding. Alternatieven zijn overwogen, eerste indruk was dat eigenaar ging tekenen maar ziet af van afspraak. Juridische stappen worden in gang gezet 2. Tijdig in gesprek gaan met de eigenaar 3. Alternatieve locatie hebben | W40: 1. Jarno Sman | X40: 1. Gereed | Y40: Alle ZRO's zijn getekend. | Z40: 2 | AA40: 7 | AB40: 2 | AC40: 7 | AD40: 0 | AE40: 4 | AF40: =IFERROR(Tabel2[[#This Row],[Kans ]]*SUM(Tabel2[[#This Row],[Tijd ]:[Omgeving ]]),0) -> 40 | AG40: =IF(F$2<KWANTIFICEERTABELLEN!B$17,_xlfn.XLOOKUP(Tabel2[[#This Row],[Kans ]],KWANTIFICEERTABELLEN!$B$6:$B$13,KWANTIFICEERTABELLEN!I$6:I$13,), IF(AND(F$2>KWANTIFICEERTABELLEN!B$17,$F$2<KWANTIFICEERTABELLEN!B$30),_xlfn.XLOOKUP(Tabel2[[#This Row],[Kans ]],KWANTIFICEERTABELLEN!$B$19:$B$26,KWANTIFICEERTABELLEN!I$19:I$26), IF(F$2>KWANTIFICEERTABELLEN!B$30,_xlfn.XLOOKUP(Tabel2[[#This Row],[Kans ]],KWANTIFICEERTABELLEN!$B$32:$B$39,KWANTIFICEERTABELLEN!I$32:I$39)))) -> 0.1 | AH40: =IF(F$2<KWANTIFICEERTABELLEN!B$17,_xlfn.XLOOKUP(Tabel2[[#This Row],[Geld ]],KWANTIFICEERTABELLEN!$B$6:$B$13,KWANTIFICEERTABELLEN!J$6:J$13,), IF(AND(F$2>KWANTIFICEERTABELLEN!B$17,$F$2<KWANTIFICEERTABELLEN!B$30),_xlfn.XLOOKUP(Tabel2[[#This Row],[Geld ]],KWANTIFICEERTABELLEN!$B$19:$B$26,KWANTIFICEERTABELLEN!J$19:J$26), IF(F$2>KWANTIFICEERTABELLEN!B$30,_xlfn.XLOOKUP(Tabel2[[#This Row],[Geld ]],KWANTIFICEERTABELLEN!$B$32:$B$39,KWANTIFICEERTABELLEN!J$32:J$39)))) -> 7500 | AI40: =IFERROR(Tabel2[[#This Row],[Kans ]]*Tabel2[[#This Row],[Rekenwaarde kosten]],0) -> 750 | AJ40: =IF(F$2<KWANTIFICEERTABELLEN!B$4,VLOOKUP(Tabel2[[#This Row],[Tijd ]],KWANTIFICEERTABELLEN!$B$6:$D$13,3,FALSE()), IF(AND(F$2>KWANTIFICEERTABELLEN!B$4,$F$2<KWANTIFICEERTABELLEN!B$30),VLOOKUP(Tabel2[[#This Row],[Tijd ]],KWANTIFICEERTABELLEN!$B$19:$D$26,3,FALSE()), IF(F$2>KWANTIFICEERTABELLEN!B$30,VLOOKUP(Tabel2[[#This Row],[Tijd ]],KWANTIFICEERTABELLEN!$B$32:$D$39,3,FALSE()),))) -> > 2 maanden
B41: 30 | D41: De grondaankoop voor MSR-8 is niet tijdig verkregen waardoor het station niet kan worden geplaatst | E41: 1. Perceeleigenaar gaat niet akkoord met de geboden voorwaarden of de locatie van het station; 2. ZRO-proces niet tijdig of niet volledig doorlopen; 3. Beperkte capaciteit bij afdeling Grond & Recht voor tijdige behandeling van het dossier. | F41: 1. MSR-8 kan niet worden geplaatst op de beoogde locatie, waardoor het net niet kan worden overgenomen; 2. Afhankelijke uitvoeringswerkzaamheden moeten worden uitgesteld; 3. IBN datum verschuift met extra kosten als gevolg. | H41: Vervallen | I41: Isabel Gheza | J41: Liander | K41: Bouwteam | R41: =IFERROR(Tabel2[[#This Row],[Kans]]*SUM(Tabel2[[#This Row],[Tijd]:[Omgeving]]),0) -> 0 | V41: 1. Gesprekken lopen bij grond en recht, voorlopig status monitoren of weerstand wordt ervaren gedurende de gesprekken | W41: 1. Jarno Sman | X41: 1. 10-12-2025 | Z41: 2 | AA41: 6 | AB41: 3 | AC41: 1 | AD41: 0 | AE41: 4 | AF41: =IFERROR(Tabel2[[#This Row],[Kans ]]*SUM(Tabel2[[#This Row],[Tijd ]:[Omgeving ]]),0) -> 28 | AG41: =VLOOKUP(Tabel2[[#This Row],[Kans ]],KWANTIFICEERTABELLEN!$B$19:$J$26,8,FALSE()) -> 0.1 | AH41: =IF(F$2<KWANTIFICEERTABELLEN!B$4,VLOOKUP(Tabel2[[#This Row],[Geld ]],KWANTIFICEERTABELLEN!$B$6:$J$13,9,FALSE()), IF(AND(F$2>KWANTIFICEERTABELLEN!B$4,$F$2<KWANTIFICEERTABELLEN!B$30),VLOOKUP(Tabel2[[#This Row],[Geld ]],KWANTIFICEERTABELLEN!$B$19:$J$26,9,FALSE()), IF(F$2>KWANTIFICEERTABELLEN!B$30,VLOOKUP(Tabel2[[#This Row],[Geld ]],KWANTIFICEERTABELLEN!$B$32:$J$39,9,FALSE()),))) -> 17500 | AI41: =IFERROR(Tabel2[[#This Row],[Kans ]]*Tabel2[[#This Row],[Rekenwaarde kosten]],0) -> 1750 | AJ41: =IF(F$2<KWANTIFICEERTABELLEN!B$4,VLOOKUP(Tabel2[[#This Row],[Tijd ]],KWANTIFICEERTABELLEN!$B$6:$D$13,3,FALSE()), IF(AND(F$2>KWANTIFICEERTABELLEN!B$4,$F$2<KWANTIFICEERTABELLEN!B$30),VLOOKUP(Tabel2[[#This Row],[Tijd ]],KWANTIFICEERTABELLEN!$B$19:$D$26,3,FALSE()), IF(F$2>KWANTIFICEERTABELLEN!B$30,VLOOKUP(Tabel2[[#This Row],[Tijd ]],KWANTIFICEERTABELLEN!$B$32:$D$39,3,FALSE()),))) -> 6 - 8 weken
...

Sheet KWANTIFICEERTABELLEN
B3: Kwantificeertabel Kleine projecten
B4: 5000000
B5: Schaal | C5: Kans | D5: Tijd | E5: Geld | F5: Kwaliteit | G5: Veiligheid | H5: Omgeving | I5: Rekenwaarde kans | J5: Rekenwaarde kosten
B6: 0 | C6: 0 | D6: Geen impact | E6: Geen impact | F6: Geen impact | G6: Geen impact | H6: Geen impact | I6: 0 | J6: 0
B7: 1 | C7: < 5 % | D7: < 0.5 week | E7: < € 5.000 | F7: Vragen binnen projectteam zonder vervolgacties | G7: Gering incident, maar geen EHBO nodig | H7: Interne aandacht | I7: 0.05 | J7: 2500
